Workbook
Name __MAIN__: #REF!
Name __qIsGrup__: #REF!
Name __qMetPoz__: #REF!
Name __qMetraj__: #REF!

Sheet Sayfa1
E1: Hesaplamalar
F2: Değişiklik yapılacak kısımlar sarı ile işaretlidir.
E5: Atık Türü
F6: Adet | G6: Ağırlık (kg/adet) | H6: Alan m2 (oda) | I6: Oda Adet | J6: Daire | K6: Toplam
E7: Tuğla (13,5 Blok Tuğla) | F7: 22 | G7: 3 | H7: 8 | I7: 3 | J7: 10 | K7: =F7*G7*H7*I7*J7 -> 15840
E8: Tuğla (24 Blok Tuğla) | F8: 18 | G8: 7.5 | H8: 7 | I8: 3 | J8: 0 | K8: =F8*G8*H8*I8*J8 -> 0
F10: Birim Ağırlık (kg/m2) | G10: Alan m2 (oda) | H10: Oda Adet | I10: Daire | J10: Toplam
E11: Sıvalı Duvar (13,5 cm kalınlık) | F11: 220 | G11: 8 | H11: 3 | I11: 10 | J11: =F11*G11*H11*I11 -> 52800
E12: Sıvalı Duvar (25 cm kalınlık) | F12: 240 | G12: 1 | H12: 2 | I12: 0 | J12: =F12*G12*H12*I12 -> 0
E15: Atık Türü | F15: Özgül Ağırlık (kg/m3) | G15: Kat Alan (m2) | H15: Yükseklik (m) | I15: Toplam Kat Sayısı | J15: Toplam (kg)
E16: Kuru Beton | F16: 2400 | G16: 85 | H16: 0.15 | I16: 6 | J16: =F16*G16*H16*I16 -> 183600
E17: Yaş Beton | F17: 2500 | G17: 200 | H17: 0.15 | I17: 0 | J17: =F17*G17*H17*I17 -> 0
E19: Atık Türü | F19: Kalınlık (m) | G19: Birim Ağırlık (kg/m2) | J19: Daire | K19: Toplam (kg)
E20: Pvc pencere | F20: Çerçeve/kanat genişlikleri (m) 94 mm ila 175 mm | G20: Topal profil genişlikleri (m) 114 mm ila 218 mm | H20: Ağırlık (kg/m2) | I20: Adet Pencere (1 Daire) | J20: Toplam Daire | K20: Toplam (kg)
F21: 0.1 | G21: 0.1 | H21: 15 | I21: 6 | J21: 0 | K21: =F21*G21*H21*I21*J21 -> 0
E22: Ahşap Pencere | F22: Çerçeve/kanat genişlikleri (m) 94 mm ila 175 mm | G22: Topal profil genişlikleri (m) 114 mm ila 218 mm | H22: Ağırlık (kg/m2) | I22: Adet Pencere (1 Daire) | J22: Toplam Daire | K22: Toplam (kg)
F23: 0.1 | G23: 0.15 | H23: 5 | I23: 6 | J23: 0 | K23: =F23*G23*H23*I23*J23 -> 0
E24: Atık Türü | F24: Birim Ağırlık (kg/m2) | G24: Alan m2 (oda) | H24: Oda Adet | I24: Toplam Daire | J24: Toplam
E25: Laminant Parke (ahşap) | F25: 2.4 | G25: 8 | H25: 3 | I25: 6 | J25: =F25*G25*H25*I25 -> 345.6
E26: Toplam Ahşap | K26: =K23+J25 -> 345.6
E27: Atık Türü | F27: Ağırlık (kg/m2) | G27: Çatı Alan (m2) | H27: Toplam (kg)
E28: Kiremit | F28: 45 | G28: 85 | H28: =F28*G28 -> 3825
E29: Seramik (tezgah alanı) | F29: Ağırlık (kg/m2) | G29: 125 | H29: Kenar uzunluk uzun (m) | I29: Toplam (kg)
F30: 24.5 | G30: 0.6 | H30: 3 | I30: =F30*G30*H30 -> 44.1
E31: Seramik (adet üzerinden) | F31: 1 adet seramik (kg) | G31: Adet | H31: Toplam (kg)
F32: 4 | G32: 360 | H32: =F32*G32 -> 1440 | J32: =I30+H32 -> 1484.1
E33: Toplam | I33: =H32+I30+H28 -> 5309.1
E35: Atık Türü | F35: Birim Ağırlık (kg/m2) | G35: Alan m2 (oda) | H35: Oda Adet | I35: Kat | J35: Daire | K35: Toplam
E36: Laminant Parke | F36: 2.4 | G36: 6 | H36: 3 | I36: 6 | J36: 12 | K36: =F36*G36*H36*I36*J36 -> 3110.4
E38: Atık Türü | F38: Ağırlık / adet (g/adet) | G38: Adet | H38: Toplam (kg)
E39: floresan lamba | F39: 71 | G39: 0 | H39: =F39*G39/100 -> 0
F40: Ağırlık /lamba (mg) | G40: Adet | H40: Toplam (g)
E41: Civa içeriği | F41: 2 | G41: 0 | H41: =F41*G41/1000 -> 0
E42: Flüoresan lambalar ve diğer cıva içeren atıklar (kg) | H42: =H41+H39*0.001 -> 0
E44: Atık Türü | F44: Kişi başı atık kağıt miktarı (kg/kişi) | G44: Şantiye ofisinde çalışacak işçi sayısı | H44: Şantiye Süresi (gün) | I44: Toplam k(kg/ay)
E45: Kağıt karton | F45: 0.6 | G45: 4 | H45: 5 | I45: =F45*G45*H45 -> 12
E46: Atık Türü | F46: Ağırlık/ Adet | G46: Bir dairedeki cam sayısı | H46: Daire | I46: Toplam (kg)
E47: Cam | F47: 10 | G47: 6 | H47: 0 | I47: =F47*G47*H47 -> 0
E48: Atık Türü | F48: Ağırlık (kg/m2) (35-45kg/m2) | G48: Temel Alanı (m2) | H48: Toplam
E49: Demir (temelde) | F49: 40 | G49: 85 | H49: =F49*G49 -> 3400
...

Sheet Sayfa2
E6: Atık Kodu | F6: Atık Kodu Tanımı | G6: Miktar
E7: 15 01 10* | F7: Tehlikeli maddelerin kalıntılarını içeren ya da tehlikeli maddelerle kontamine olmuş ambalajlar | G7: 0
E8: 17 02 04* | F8: Tehlikeli maddeler içeren ya da tehlikeli maddelerle kontamine olmuş ahşap, cam ve plastik | G8: 0
E9: 20 01 21* | F9: Flüoresan lambalar ve diğer cıva içeren atıklar | G9: =Sayfa1!H42 -> 0
E10: 16 02 11* | F10: Kloroflorokarbon, HCFC, HFC içeren ıskarta ekipmanlar | G10: 0
E11: 20 01 23* | F11: Kloroflorokarbonlar içeren ıskartaya çıkartılmış ekipmanlar | G11: 0
E12: 17 09 02* | F12: PCB içeren inşaat ve yıkıntı atıkları (örneğin PCB içeren dolgu macunları, PCB içeren reçine bazlı taban kaplama malzemeleri, PCB içeren kaplanmış sırlama birimleri, PCB içeren kapasitörler) | G12: 0
E13: 17 06 05* | F13: Asbest içeren inşaat malzemeleri | G13: =Sayfa1!K54 -> 0
E14: 15 01 03 | F14: Ahşap ambalaj | G14: 0
F15: tuğla | G15: =Sayfa1!K7 -> 15840
E16: 17 01 01 | F16: Beton | G16: =Sayfa1!J16 -> 183600
E17: 17 01 03 | F17: Kiremitler ve seramikler | G17: =Sayfa1!I33 -> 5309.1
E18: 17 02 01 | F18: Ahşap | G18: =Sayfa1!K26 -> 345.6
E19: 17 05 04 | F19: 17 05 03 dışındaki toprak ve taşlar
E20: 17 08 02 | F20: 17 08 01 dışındaki alçı bazlı inşaat malzemeleri | G20: =Sayfa1!J11 -> 52800
E21: 20 01 08 | F21: Biyolojik olarak bozunabilir mutfak ve kantin atıkları (8) | G21: 0
E22: 17 04 07 | F22: Karışık metaller | G22: =Sayfa1!I52 -> 20400
E23: 15 01 01 | F23: Kağıt ve karton ambalaj | G23: =Sayfa1!I45 -> 12
E24: 15 01 02 | F24: Plastik ambalaj | G24: =Sayfa1!K21 -> 0
E25: 15 01 04 | F25: Metalik ambalaj | G25: 0
E26: 15 01 07 | F26: Cam ambalaj | G26: =Sayfa1!I47 -> 0
E27: Toplam | G27: =SUM(G7:G26) -> 278306.7
E32: (8) | F32: 10/5/2005 tarihli ve 5346 sayılı Yenilenebilir Enerji Kaynaklarının Elektrik Enerjisi Üretimi Amaçlı Kullanımına İlişkin Kanunun 3 üncü maddesinin dokuzuncu fıkrasında tanımlanan atıklardır. Bu atıkların yönetiminde bu Yönetmelikle getirilen tüm yükümlülüklere uyulur.
